Workbook

Sheet old
A1: Date (MM-YY) | B1: Ratio of General provisions/ collective 3M impairment provisions to Net total loans(%) | C1: Transformed | H1: Date (qqyy) | I1: Quarterly impaired prop loans ratio
A2: 35796 | B2: 2.0733963 | C2: =B2*3.09 -> 6.4067945 | H2: 1Q98 | I2: =OFFSET(C$2, (ROWS(C$2:C2)-1)*3,0,1,1) -> 6.4067945
A3: 35827 | B3: 2.1623627 | C3: =B3*3.09 -> 6.6817006 | H3: 2Q98 | I3: =OFFSET(C$2, (ROWS(C$2:C3)-1)*3,0,1,1) -> 6.5749225
A4: 35855 | B4: 2.2284414 | C4: =B4*3.09 -> 6.8858838 | H4: 3Q98 | I4: =OFFSET(C$2, (ROWS(C$2:C4)-1)*3,0,1,1) -> 6.7755827
A5: 35886 | B5: 2.1278066 | C5: =B5*3.09 -> 6.5749225 | H5: 4Q98 | I5: =OFFSET(C$2, (ROWS(C$2:C5)-1)*3,0,1,1) -> 6.6921163
A6: 35916 | B6: 2.1466908 | C6: =B6*3.09 -> 6.6332746 | H6: 1Q99 | I6: =OFFSET(C$2, (ROWS(C$2:C6)-1)*3,0,1,1) -> 6.7218738
A7: 35947 | B7: 2.1640017 | C7: =B7*3.09 -> 6.6867654 | H7: 2Q99 | I7: =OFFSET(C$2, (ROWS(C$2:C7)-1)*3,0,1,1) -> 6.7875285
A8: 35977 | B8: 2.1927452 | C8: =B8*3.09 -> 6.7755827 | H8: 3Q99 | I8: =OFFSET(C$2, (ROWS(C$2:C8)-1)*3,0,1,1) -> 6.8590608
A9: 36008 | B9: 2.1911124 | C9: =B9*3.09 -> 6.7705375 | H9: 4Q99 | I9: =OFFSET(C$2, (ROWS(C$2:C9)-1)*3,0,1,1) -> 6.6672659
A10: 36039 | B10: 2.0296876 | C10: =B10*3.09 -> 6.2717346 | H10: 1Q00 | I10: =OFFSET(C$2, (ROWS(C$2:C10)-1)*3,0,1,1) -> 6.8679028
A11: 36069 | B11: 2.1657334 | C11: =B11*3.09 -> 6.6921163 | H11: 2Q00 | I11: =OFFSET(C$2, (ROWS(C$2:C11)-1)*3,0,1,1) -> 6.7862531
A12: 36100 | B12: 2.0321314 | C12: =B12*3.09 -> 6.2792861 | H12: 3Q00 | I12: =OFFSET(C$2, (ROWS(C$2:C12)-1)*3,0,1,1) -> 6.7663872
A13: 36130 | B13: 2.2017095 | C13: =B13*3.09 -> 6.8032824 | H13: 4Q00 | I13: =OFFSET(C$2, (ROWS(C$2:C13)-1)*3,0,1,1) -> 6.8163741
... A113: 39173 | B113: 1.6907634 | C113: =B113*3.09 -> 5.2244588 | H113: 4Q25 | I113: =OFFSET(C$2, (ROWS(C$2:C113)-1)*3,0,1,1) -> 1.122044
A114: 39203 | B114: 1.6955962 | C114: =B114*3.09 -> 5.2393923
A115: 39234 | B115: 1.681609 | C115: =B115*3.09 -> 5.1961719
A116: 39264 | B116: 1.6851009 | C116: =B116*3.09 -> 5.2069618
A117: 39295 | B117: 1.6986555 | C117: =B117*3.09 -> 5.2488455
A118: 39326 | B118: 1.6926746 | C118: =B118*3.09 -> 5.2303646
A119: 39356 | B119: 1.6924621 | C119: =B119*3.09 -> 5.2297079
A120: 39387 | B120: 1.6893649 | C120: =B120*3.09 -> 5.2201376
A121: 39417 | B121: 1.6928871 | C121: =B121*3.09 -> 5.2310212
A122: 39448 | B122: 1.6935666 | C122: =B122*3.09 -> 5.2331207
A123: 39479 | B123: 1.7087358 | C123: =B123*3.09 -> 5.2799936
A124: 39508 | B124: 1.6963911 | C124: =B124*3.09 -> 5.2418486
A125: 39539 | B125: 1.6995694 | C125: =B125*3.09 -> 5.2516696
... A132: 39753 | B132: 1.7108221 | C132: =B132*3.09 -> 5.2864403
A133: 39783 | B133: 1.7043077 | C133: ='Source Data'!D37 -> 5.6067653
A134: 39814 | B134: 1.6911447 | C134: ='Source Data'!D38 -> 5.6354943
A135: 39845 | B135: 1.7012736 | C135: ='Source Data'!D39 -> 5.6480798
A136: 39873 | B136: 1.6878245 | C136: ='Source Data'!D40 -> 5.5797844
A137: 39904 | B137: 1.7010436 | C137: ='Source Data'!D41 -> 5.5029542
A138: 39934 | B138: 1.6837435 | C138: ='Source Data'!D42 -> 5.4874282
A139: 39965 | B139: 1.6814642 | C139: ='Source Data'!D43 -> 5.3323287
A140: 39995 | B140: 1.6913845 | C140: ='Source Data'!D44 -> 5.1450754
A141: 40026 | B141: 1.714603 | C141: ='Source Data'!D45 -> 5.1111283
A142: 40057 | B142: 1.6699556 | C142: ='Source Data'!D46 -> 5.0471348
A143: 40087 | B143: 1.6902125 | C143: ='Source Data'!D47 -> 4.9525069
A144: 40118 | B144: 1.6529622 | C144: ='Source Data'!D48 -> 4.3732317
A145: 40148 | B145: 1.625936 | C145: ='Source Data'!D49 -> 4.2632849
...

Sheet Source Data
A1: ﻿ | B1: Loans: BS: Purchase of Residential Property | C1: Impaired loans value of residential property (RM mil) | D1: Impaired loans ratio to total outstanding residential prop loans | E1: Comparing with old data series on total impaired loan ratio | F1: Deriving a multiplier to proxy prop loan impairment ratio with total loan
A2: 38718 | B2: 149801.12
A3: 38749 | B3: 150489.04
A4: 38777 | B4: 152167.74
A5: 38808 | B5: 152023.43
A6: 38838 | B6: 154154.43
A7: 38869 | B7: 155516.83
A8: 38899 | B8: 156667.53
A9: 38930 | B9: 157886.87
A10: 38961 | B10: 158889.7
A11: 38991 | B11: 160073.78
A12: 39022 | B12: 161110.87
A13: 39052 | B13: 161832.33
... A35: 39722 | B35: 188298.11
A36: 39753 | B36: 189887.9 | F36: =AVERAGE(F37:F49) -> 3.088948
A37: 39783 | B37: 191527.54 | C37: 10738.5 | D37: =C37/B37*100 -> 5.6067653 | E37: 1.7043077 | F37: =D37/E37 -> 3.2897612
A38: 39814 | B38: 192909.43 | C38: 10871.4 | D38: =C38/B38*100 -> 5.6354943 | E38: 1.6911447 | F38: =D38/E38 -> 3.3323548
A39: 39845 | B39: 193919 | C39: 10952.7 | D39: =C39/B39*100 -> 5.6480798 | E39: 1.7012736 | F39: =D39/E39 -> 3.3199127
A40: 39873 | B40: 195002.16 | C40: 10880.7 | D40: =C40/B40*100 -> 5.5797844 | E40: 1.6878245 | F40: =D40/E40 -> 3.3059032
A41: 39904 | B41: 196507.18 | C41: 10813.7 | D41: =C41/B41*100 -> 5.5029542 | E41: 1.7010436 | F41: =D41/E41 -> 3.235046
A42: 39934 | B42: 197956.12 | C42: 10862.7 | D42: =C42/B42*100 -> 5.4874282 | E42: 1.6837435 | F42: =D42/E42 -> 3.2590642
A43: 39965 | B43: 199203.78 | C43: 10622.2 | D43: =C43/B43*100 -> 5.3323287 | E43: 1.6814642 | F43: =D43/E43 -> 3.1712413
A44: 39995 | B44: 200877.52 | C44: 10335.3 | D44: =C44/B44*100 -> 5.1450754 | E44: 1.6913845 | F44: =D44/E44 -> 3.0419313
A45: 40026 | B45: 202667.58 | C45: 10358.6 | D45: =C45/B45*100 -> 5.1111283 | E45: 1.714603 | F45: =D45/E45 -> 2.9809398
A46: 40057 | B46: 204351.58 | C46: 10313.9 | D46: =C46/B46*100 -> 5.0471348 | E46: 1.6699556 | F46: =D46/E46 -> 3.0223167
A47: 40087 | B47: 206541.86 | C47: 10229 | D47: =C47/B47*100 -> 4.9525069 | E47: 1.6902125 | F47: =D47/E47 -> 2.930109
A48: 40118 | B48: 207439.27 | C48: 9071.8 | D48: =C48/B48*100 -> 4.3732317 | E48: 1.6529622 | F48: =D48/E48 -> 2.6456936
A49: 40148 | B49: 209364.38 | C49: 8925.8 | D49: =C49/B49*100 -> 4.2632849 | E49: 1.625936 | F49: =D49/E49 -> 2.6220497
A50: 40179 | B50: 211610.32 | C50: 8734.2 | D50: =C50/B50*100 -> 4.1274925
A51: 40210 | B51: 213276.24 | C51: 8944.9 | D51: =C51/B51*100 -> 4.1940442
A52: 40238 | B52: 215171.37 | C52: 8067.4 | D52: =C52/B52*100 -> 3.7492907
A53: 40269 | B53: 217527.57 | C53: 8224.1 | D53: =C53/B53*100 -> 3.7807161
A54: 40299 | B54: 219691.88 | C54: 8160.3 | D54: =C54/B54*100 -> 3.7144295
A55: 40330 | B55: 221746.73 | C55: 7853.2 | D55: =C55/B55*100 -> 3.5415178
A56: 40360 | B56: 224907.89 | C56: 7798.6 | D56: =C56/B56*100 -> 3.467464
A57: 40391 | B57: 227557.44 | C57: 7748.5 | D57: =C57/B57*100 -> 3.4050743
A58: 40422 | B58: 229617.1 | C58: 7795.2 | D58: =C58/B58*100 -> 3.3948691
A59: 40452 | B59: 232038.14 | C59: 7705.1 | D59: =C59/B59*100 -> 3.3206179
A60: 40483 | B60: 234389.28 | C60: 7783.5 | D60: =C60/B60*100 -> 3.3207576
A61: 40513 | B61: 237005.43 | C61: 7724.2 | D61: =C61/B61*100 -> 3.2590814
...
